Workbook
Name DCF_Share_Price: #REF!
Name Market_return: assumptions!#REF!

Sheet Sheet1

Sheet assumptions
B1: ASSUMPTIONS
B2: Financial Year | D2: 2023A | E2: 2024A | F2: 2025A | G2: 2026E | H2: 2027E | I2: 2028E | J2: 2029E | K2: 2030E
B4: Revenue Growth
B5: Revenue Growth Rate | D5: 0.188 | E5: 0.0094757835 | F5: -0.029306992 | G5: 0.07 | H5: =G5+1% -> 0.08 | I5: =H5+1% -> 0.09 | J5: =I5+1% -> 0.1 | K5: =J5+1% -> 0.11
B6: Revenue | D6: 96773 | E6: 97690 | F6: 94827 | G6: =F6*(1+G5) -> 101464.89 | H6: =G6*(1+H5) -> 109582.08 | I6: =H6*(1+I5) -> 119444.47 | J6: =I6*(1+J5) -> 131388.92 | K6: =J6*(1+K5) -> 145841.7
B7: Depreciation | D7: 4667 | E7: 5368 | F7: 6148 | G7: 5682.3533 | H7: 6136.9416 | I7: 6689.2663 | J7: 7358.193 | K7: 8167.5942
B8: EBITDA | D8: 13558 | E8: 12444 | F8: 10503 | G8: 13378.417 | H8: 14448.691 | I8: 15749.073 | J8: 17323.98 | K8: 19229.618
B9: Margin
B10: EBIT | G10: ='[1]income statement'!$F$14 -> 7696.064 | H10: ='[1]income statement'!$G$14 -> 8311.7491 | I10: ='[1]income statement'!$H$14 -> 9059.8066 | J10: ='[1]income statement'!$I$14 -> 9965.7872 | K10: ='[1]income statement'!$J$14 -> 11062.024
B11: Gross Margin | D11: 0.18 | E11: 0.18 | F11: 0.18 | G11: 0.18 | H11: 0.18 | I11: 0.18 | J11: 0.18 | K11: 0.18
B12: EBIT Margin | D12: 0.0918748 | E12: 0.072433207 | F12: 0.045925738 | G12: =G10/G6 -> 0.075849528 | H12: =H10/H6 -> 0.075849528 | I12: =I10/I6 -> 0.075849528 | J12: =J10/J6 -> 0.075849528 | K12: =K10/K6 -> 0.075849528
B13: Effective Tax Rate | D13: -0.50145393 | E13: 0.20433815 | F13: 0.21 | G13: =F13 -> 0.21 | H13: 0.21 | I13: 0.21 | J13: 0.21 | K13: 0.21
B14: DCF & WACC
B15: WC as % of Revenue Change | C15: 0.015
B16: Capex | D16: ='[1]Dep Capex Schedule'!$C$10 -> 10844 | E16: ='[1]Dep Capex Schedule'!$D$10 -> 11479 | F16: ='[1]Dep Capex Schedule'!$E$10 -> 10955 | G16: ='[1]Dep Capex Schedule'!$F$10 -> 10146.489 | H16: ='[1]Dep Capex Schedule'!$G$10 -> 10958.208 | I16: ='[1]Dep Capex Schedule'!$H$10 -> 11944.447 | J16: ='[1]Dep Capex Schedule'!$I$10 -> 13138.892 | K16: ='[1]Dep Capex Schedule'!$J$10 -> 14584.17
B17: Non cash working capital inc/dec
B18: EQUITY | G18: 1200000 | H18: 1200000 | I18: 1200000 | J18: 1200000 | K18: 1200000
B19: DEBT | G19: 7500 | H19: =G19-500 -> 7000 | I19: =H19-500 -> 6500 | J19: =I19-500 -> 6000 | K19: =J19-500 -> 5500
B20: Risk-Free Rate (10-Yr Treasury) | C20: 0.043
B21: Equity Risk Premium | C21: 0.045
B22: Beta (5-Year Monthly vs S&P500) | C22: 1.93
B23: Cost of Equity [Ke = Rf + β×ERP] | C23: =C20+C22*C21 -> 0.12985
B24: Pre-Tax Cost of Debt | C24: 0.055
B25: Weight of Equity (E/V) | C25: =C33/(C33+G19) -> 0.99410527
B26: Weight of Debt (D/V) | C26: =1-C25 -> 0.0058947265
B27: WACC [Ke×E/V + Kd×(1-t)×D/V] | C27: =C23*C25+C24*(1-F13)*C26 -> 0.1293407
B28: Terminal Growth Rate | C28: 0.025
B29: EV/EBIDA Multiple | C29: 20
B30: Shares Outstanding ($mm) | C30: 3503.6667
B31: Net Cash ($mm) | C31: 72163
B32: Share Price | C32: 361
B33: Market Cap | C33: =C32*C30 -> 1264823.7

Sheet FCF
B3: Financial Year | C3: FY2026E | D3: FY2027E | E3: FY2028E | F3: FY2029E | G3: FY2030E
B4: FREE CASH FLOW BUILD ($mm)
B5: EBIT | C5: =assumptions!G10 -> 7696.064 | D5: =assumptions!H10 -> 8311.7491 | E5: =assumptions!I10 -> 9059.8066 | F5: =assumptions!J10 -> 9965.7872 | G5: =assumptions!K10 -> 11062.024
B6: Less: Taxes on EBIT | C6: =C5*assumptions!G13 -> 1616.1734 | D6: =D5*assumptions!H13 -> 1745.4673 | E6: =E5*assumptions!I13 -> 1902.5594 | F6: =F5*assumptions!J13 -> 2092.8153 | G6: =G5*assumptions!K13 -> 2323.025
B7: NOPAT (Net Operating Profit After Tax) | C7: =C5-C6 -> 6079.8906 | D7: =D5-D6 -> 6566.2818 | E7: =E5-E6 -> 7157.2472 | F7: =F5-F6 -> 7872.9719 | G7: =G5-G6 -> 8738.9988
B9: Depreciation & Amortization | C9: =assumptions!G7 -> 5682.3533 | D9: =assumptions!H7 -> 6136.9416 | E9: =assumptions!I7 -> 6689.2663 | F9: =assumptions!J7 -> 7358.193 | G9: =assumptions!K7 -> 8167.5942
B10: Capital Expenditures | C10: =assumptions!G16 -> 10146.489 | D10: =assumptions!H16 -> 10958.208 | E10: =assumptions!I16 -> 11944.447 | F10: =assumptions!J16 -> 13138.892 | G10: =assumptions!K16 -> 14584.17
B11: Change in Working Capital | C11: =(assumptions!G6-assumptions!F6)*assumptions!$C$15 -> 99.56835 | D11: =(assumptions!H6-assumptions!G6)*assumptions!$C$15 -> 121.75787 | E11: =(assumptions!I6-assumptions!H6)*assumptions!$C$15 -> 147.93581 | F11: =(assumptions!J6-assumptions!I6)*assumptions!$C$15 -> 179.1667 | G11: =(assumptions!K6-assumptions!J6)*assumptions!$C$15 -> 216.79171
B12: Unlevered Free Cash Flow | C12: =C7+C9-C10+C11 -> 1715.3232 | D12: =D7+D9-D10+D11 -> 1866.7732 | E12: =E7+E9-E10+E11 -> 2050.0025 | F12: =F7+F9-F10+F11 -> 2271.44 | G12: =G7+G9-G10+G11 -> 2539.2151
B15: WACC Calculations ($mm)
B17: E/E+D | C17: =assumptions!G18/(assumptions!G18+assumptions!G19) -> 0.99378882 | D17: =assumptions!H18/(assumptions!H18+assumptions!H19) -> 0.9942005 | E17: =assumptions!I18/(assumptions!I18+assumptions!I19) -> 0.99461252 | F17: =assumptions!J18/(assumptions!J18+assumptions!J19) -> 0.99502488 | G17: =assumptions!K18/(assumptions!K18+assumptions!K19) -> 0.99543758
B18: D/E+D | C18: =assumptions!G19/(assumptions!G18+assumptions!G19) -> 0.0062111801 | D18: =assumptions!H19/(assumptions!H18+assumptions!H19) -> 0.0057995029 | E18: =assumptions!I19/(assumptions!I18+assumptions!I19) -> 0.0053874845 | F18: =assumptions!J19/(assumptions!J18+assumptions!J19) -> 0.0049751244 | G18: =assumptions!K19/(assumptions!K18+assumptions!K19) -> 0.0045624222
B19: WACC | C19: =C17*assumptions!$C23+FCF!C18*assumptions!$C24*(1-assumptions!$F13) -> 0.12931335 | D19: =D17*assumptions!$C23+FCF!D18*assumptions!$C24*(1-assumptions!$F13) -> 0.12934892 | E19: =E17*assumptions!$C23+FCF!E18*assumptions!$C24*(1-assumptions!$F13) -> 0.12938452 | F19: =F17*assumptions!$C23+FCF!F18*assumptions!$C24*(1-assumptions!$F13) -> 0.12942015 | G19: =G17*assumptions!$C23+FCF!G18*assumptions!$C24*(1-assumptions!$F13) -> 0.12945581
B22: Terminal Value Calculations ($mm)
B24: EBITDA | C24: =assumptions!G8 -> 13378.417 | D24: =assumptions!H8 -> 14448.691 | E24: =assumptions!I8 -> 15749.073 | F24: =assumptions!J8 -> 17323.98 | G24: =assumptions!K8 -> 19229.618
B25: FCF | C25: =C12 -> 1715.3232 | D25: =D12 -> 1866.7732 | E25: =E12 -> 2050.0025 | F25: =F12 -> 2271.44 | G25: =G12 -> 2539.2151
B27: Perpetuity Growth TV | G27: =(G25*(1+assumptions!C28))/(FCF!G19-assumptions!C28) -> 24916.714
B28: EV/ EBITDA TV | G28: =G24*assumptions!C29 -> 384592.36
B29: Average | G29: =AVERAGE(G27:G28) -> 204754.54
B31: Discounted cashflows ($mm)
B33: FCF | C33: =C12 -> 1715.3232 | D33: =D12 -> 1866.7732 | E33: =E12 -> 2050.0025 | F33: =F12 -> 2271.44 | G33: =G12 -> 2539.2151
B34: Terminal value | G34: =G29 -> 204754.54
B35: Discount factor | C35: =1/(1+C19)^1 -> 0.88549382 | D35: =1/(1+D19)^2 -> 0.78404992 | E35: =1/(1+E19)^3 -> 0.69418385 | F35: =1/(1+F19)^4 -> 0.61457922 | G35: =1/(1+G19)^5 -> 0.54406876
B37: PV of FCF | C37: =C33*C35 -> 1518.9081 | D37: =D33*D35 -> 1463.6433 | E37: =E33*E35 -> 1423.0786 | F37: =F33*F35 -> 1395.9799 | G37: =G33*G35 -> 1381.5076 | I37: Market Value vs Intrinsic Value
B38: PV of TV | G38: =G34*G35 -> 111400.55 | I38: Market Value | J38: =J49 -> 361
I39: Upside | J39: =(C46-J46)/J46 -> -0.84006627
B40: Enterprise Value | G40: =SUM(C37:G38) -> 118583.66 | I40: Intrinsic Value | J40: =C49 -> 54.442012
B42: Intrinsic Value ($mm) | I42: Market Value ($mm)
B43: Enterprise Value | C43: =G40 -> 118583.66 | I43: Market Cap | J43: =assumptions!C33 -> 1264823.7
B44: Net Cash(mm) | C44: =assumptions!C31 -> 72163 | I44: Net Cash | J44: =assumptions!C31 -> 72163
B46: Equity Value | C46: =C43+C44 -> 190746.66 | I46: Enterprise Value | J46: =J43-J44 -> 1192660.7
B48: Shares Outstanding ($mm) | C48: =assumptions!C30 -> 3503.6667 | I48: Shares Outstanding ($mm) | J48: =assumptions!C30 -> 3503.6667
B49: Share Price | C49: =C46/C48 -> 54.442012 | I49: Equity Value/Share | J49: =J43/J48 -> 361
B51: Sensitivity Analysis
B53: =C49 -> 54.442012 | C53: =D53-0.5% -> 0.12 | D53: =E53-0.5% -> 0.125 | E53: 0.13 | F53: =E53+0.5% -> 0.135 | G53: =F53+0.5% -> 0.14
B54: =B55-0.5% -> 0.015 | C54: 54.442012 | D54: 54.442012 | E54: 54.442012 | F54: 54.442012 | G54: 54.442012
B55: =B56-0.5% -> 0.02 | C55: 54.442012 | D55: 54.442012 | E55: 54.442012 | F55: 54.442012 | G55: 54.442012
B56: =assumptions!C28 -> 0.025 | C56: 54.442012 | D56: 54.442012 | E56: 54.442012 | F56: 54.442012 | G56: 54.442012
B57: =B56+0.5% -> 0.03 | C57: 54.442012 | D57: 54.442012 | E57: 54.442012 | F57: 54.442012 | G57: 54.442012
B58: =B57+0.5% -> 0.035 | C58: 54.442012 | D58: 54.442012 | E58: 54.442012 | F58: 54.442012 | G58: 54.442012
...
